Workbook
Name BU: #REF!
Name cc: #REF!
Name CLIENTE: #REF!
Name DELIVERY: #REF!
Name STATUS: #REF!

Sheet CC
A1: CENTRO_CUSTOS | B1: CONTRATO | C1: CLIENTE | D1: STATUS | E1: BU | F1: VERTICAL | G1: EXECUTIVO | H1: Dr_OPE | I1: SETOR
A2: 1101 | B2: DIRETORIA (1101) | C2: ADM/FIN | D2: ATIVO | E2: TX_ADM | F2: ALL | G2: PAULO MARCELO | H2: OP | I2: CORPORATIVO
A3: 1102 | B3: DIRETOR MARIO BRITO (1102) | C3: DESATIVADO | D3: INATIVO | I3: CORPORATIVO
A4: 1103 | B4: FINANCEIRO (1103) | C4: ADM/FIN | D4: ATIVO | E4: TX_ADM | F4: ALL | G4: ANDRÉ MOTA | H4: OP | I4: CORPORATIVO
A5: 1104 | B5: ADMINISTRATIVO (1104) | C5: ADM/FIN | D5: ATIVO | E5: TX_ADM | F5: ALL | G5: ANDRÉ MOTA | H5: OP | I5: CORPORATIVO
A6: 1105 | B6: DEPARTAMENTO PESSOAL (DP) (1105) | C6: RH | D6: ATIVO | E6: TX_ADM | F6: ALL | G6: VIVIANE SANTOS | H6: OP | I6: CORPORATIVO
A7: 1109 | B7: QUALIDADE (1109) | C7: QUALIDADE | D7: ATIVO | E7: TX_ADM | F7: ALL | G7: EVANDRO BRAGA | H7: OP | I7: CORPORATIVO
A8: 1110 | B8: APOIO COMERCIAL (1110) | C8: COMERCIAL | D8: ATIVO | E8: TX_ADM | F8: ALL | G8: ANDRÉ MOTA | H8: OP | I8: CORPORATIVO
A9: 1111 | B9: AQUISIÇÕES PT SOLUTIS (1111) | C9: AQUIS_ESTACAO | D9: ATIVO | E9: TX_ADM | F9: ALL | G9: ANDRÉ MOTA | H9: OP | I9: CORPORATIVO
A10: 1114 | B10: TALENT ACQUISITION (1114) | C10: RH | D10: ATIVO | E10: TX_ADM | F10: ALL | G10: VIVIANE SANTOS | H10: OP | I10: CORPORATIVO
A11: 1116 | B11: MARKETING (1116) | C11: MKT | D11: ATIVO | E11: TX_ADM | F11: ALL | G11: DEBORA LIMA | H11: OP | I11: CORPORATIVO
A12: 1117 | B12: RECURSO INTERNO (1117) | C12: ADM/FIN | D12: ATIVO | E12: TX_ADM | F12: ALL | G12: VIVIANE SANTOS | H12: OP | I12: CORPORATIVO
A13: 1118 | B13: TI INTERNA CORPORATIVA (1118) | C13: TI_PLAT_CORP | D13: ATIVO | E13: TX_ADM | F13: ALL | G13: ANDRÉ MOTA | H13: OP | I13: CORPORATIVO
A14: 1119 | B14: CDO – PRÉ VENDA (1119) | C14: DESATIVADO | D14: INATIVO | I14: CORPORATIVO
A15: 1136 | B15: CDO (1136) | C15: DESATIVADO | D15: INATIVO | I15: CORPORATIVO
A16: 1139 | B16: PSU (1139) | C16: COMERCIAL | D16: ATIVO | E16: TX_ADM | F16: ALL | G16: MARIO AMERICO | H16: OP | I16: CORPORATIVO
A17: 1140 | B17: FS (1140) | C17: COMERCIAL | D17: ATIVO | E17: TX_ADM | F17: ALL | G17: LUIS RICARDO MARTORELLI | H17: OP | I17: CORPORATIVO
A18: 1141 | B18: MS (1141) | C18: COMERCIAL | D18: ATIVO | E18: TX_ADM | F18: ALL | G18: PAULO MARCELO | H18: OP | I18: CORPORATIVO
A19: 1142 | B19: DCX (1142) | C19: DESATIVADO | D19: INATIVO | I19: CORPORATIVO
A20: 1143 | B20: ADS (1143) | C20: DESATIVADO | D20: INATIVO | I20: CORPORATIVO
A21: 1144 | B21: CPS (1144) | C21: DESATIVADO | D21: INATIVO | I21: CORPORATIVO
A22: 1145 | B22: CSA (1145) | C22: COMERCIAL | D22: INATIVO | I22: CORPORATIVO
A23: 1146 | B23: SALESFORCE (1146) | C23: PORT_FORMACAO | D23: ATIVO | E23: TX_ADM | F23: ALL | G23: NIVALDO AMORIM | H23: OP | I23: CORPORATIVO
A24: 1147 | B24: TM Telecom/Mídia (1147) | C24: DESATIVADO | D24: INATIVO | I24: CORPORATIVO
A25: 1149 | B25: INFRA DIGITAL (1149) | C25: DESATIVADO | D25: INATIVO | I25: CORPORATIVO
A26: 1150 | B26: DPO - Proteção de Dados (1150) | C26: ADM/FIN | D26: ATIVO | E26: TX_ADM | F26: ALL | G26: ANDRÉ MOTA | H26: OP | I26: CORPORATIVO
A27: 1151 | B27: RPA (1151) | C27: DESATIVADO | D27: INATIVO | I27: CORPORATIVO
A28: 1152 | B28: D&A (1152) | C28: DESATIVADO | D28: INATIVO | I28: CORPORATIVO
A29: 1153 | B29: BUSINESS PARTNER (BP) (1153) | C29: RH | D29: ATIVO | E29: TX_ADM | F29: ALL | G29: VIVIANE SANTOS | H29: OP | I29: CORPORATIVO
A30: 1154 | B30: REMUNERAÇÃO & BENEFÍCIOS (R&B) (1154) | C30: DESATIVADO | D30: INATIVO | I30: CORPORATIVO
A31: 1155 | B31: PEOPLE ENGAGEMENT (1155) | C31: MKT | D31: ATIVO | E31: TX_ADM | F31: ALL | G31: DEBORA LIMA | H31: OP | I31: CORPORATIVO
A32: 1156 | B32: TIC (1156) | C32: TIC | D32: ATIVO | E32: TX_ADM | F32: ALL | G32: ANDRÉ MOTA | H32: OP | I32: CORPORATIVO
A33: 1157 | B33: ACADEMY (1157) | C33: PORT_FORMACAO | D33: ATIVO | E33: TX_ADM | F33: ALL | G33: MANOEL NETO | H33: OP | I33: CORPORATIVO
A34: 1158 | B34: GESTÃO DE RH | C34: RH | D34: ATIVO | E34: TX_ADM | F34: ALL | G34: VIVIANE SANTOS | H34: OP | I34: CORPORATIVO
A35: 1159 | B35: SOLUTIS LABS (1159) | C35: PORT_FORMACAO | D35: ATIVO | E35: TX_ADM | F35: ALL | G35: ANA PAULA BRAUN | H35: OP | I35: CORPORATIVO
A36: 1160 | B36: IV (1160) | C36: COMERCIAL | D36: ATIVO | E36: TX_ADM | F36: ALL | G36: PAULO MARCELO | H36: OP | I36: CORPORATIVO
A37: 1161 | B37: ESTRUTURAÇÃO FINANCIAL SERVICES (1161) | C37: COMERCIAL | D37: INATIVO | I37: CORPORATIVO
A38: 1162 | B38: CONSELHO (1162) | C38: CONSELHO | D38: ATIVO | E38: TX_ADM | F38: ALL | G38: ANDRÉ MOTA | H38: OP | I38: CORPORATIVO
A39: 1163 | B39: PLATAFORMA CORPORATIVA (1163) | C39: TI_PLAT_CORP | D39: ATIVO | E39: TX_ADM | F39: ALL | G39: ANDRÉ MOTA | H39: OP | I39: CORPORATIVO
A40: 1164 | B40: PRODUTOS DIGITAIS (1164) | C40: PORT_FORMACAO | D40: ATIVO | E40: TX_ADM | F40: ALL | G40: NIVALDO AMORIM | H40: OP | I40: CORPORATIVO
...

Sheet CT A RECEBER
A1: CC | B1: Local | C1: Excecutivo | D1: Grupo Cliente | E1: CLIENTE | F1: TIPO | G1: NFE | H1: MÊS SERVIÇO | I1: VL. FATURADO | J1: VL. LIQ. PRV. | K1: EMISSÃO | L1: PREV . PAG | M1: DATA PAG. | N1: STATUS | O1: Risco | P1: NIVEL RISCO | Q1: BU | R1: Vertical | S1: Diretor de Operações | T1: A RECEBER | U1: SATUS 2 | V1: META | W1: Vencimento
A2: 1390 | B2: =IFERROR(VLOOKUP(Tabela1[[#This Row],[CC]],#REF!,5,0),"") | C2: JOSÉ NETO COELHO | D2: OI | E2: OI - DIGITAL SUPORT (1390) | F2: SERVIÇO | G2: 652 | H2: 44927 | I2: 33803.85 | J2: 32301.82 | K2: 44973 | L2: 45677 | M2: 45678 | N2: PAGO | O2: 0 | Q2: CSA | R2: UT | S2: =IFERROR(VLOOKUP(Tabela1[[#This Row],[CC]],CC!$A$1:$H$403,8,0),"") -> OP2 | T2: SIM | U2: RECUPERAÇÃO JUDICIAL
A3: 1390 | B3: =IFERROR(VLOOKUP(Tabela1[[#This Row],[CC]],#REF!,5,0),"") | C3: JOSÉ NETO COELHO | D3: OI | E3: OI - DIGITAL SUPORT (1390) | F3: SERVIÇO | G3: 1168 | H3: 45536 | I3: 185487.39 | J3: 163878.11 | K3: 45581 | L3: 45677 | M3: 45679 | N3: PAGO | O3: 0 | Q3: CSA | R3: UT | S3: =IFERROR(VLOOKUP(Tabela1[[#This Row],[CC]],CC!$A$1:$H$403,8,0),"") -> OP2
A4: 1390 | B4: =IFERROR(VLOOKUP(Tabela1[[#This Row],[CC]],#REF!,5,0),"") | C4: JOSÉ NETO COELHO | D4: OI | E4: OI - DIGITAL SUPORT (1390) | F4: SERVIÇO | G4: 1179 | H4: 45566 | I4: 184286.01 | J4: 162816.69 | K4: 45609 | L4: 45677 | M4: 45679 | N4: PAGO | O4: 0 | Q4: CSA | R4: UT | S4: =IFERROR(VLOOKUP(Tabela1[[#This Row],[CC]],CC!$A$1:$H$403,8,0),"") -> OP2
A5: 1390 | B5: =IFERROR(VLOOKUP(Tabela1[[#This Row],[CC]],#REF!,5,0),"") | C5: JOSÉ NETO COELHO | D5: OI | E5: OI - DIGITAL SUPORT (1390) | F5: SERVIÇO | G5: 1195 | H5: 45597 | I5: 184286.01 | J5: 162816.69 | K5: 45637 | L5: 45698 | M5: 45698 | N5: PAGO | O5: 0 | Q5: CSA | R5: UT | S5: =IFERROR(VLOOKUP(Tabela1[[#This Row],[CC]],CC!$A$1:$H$403,8,0),"") -> OP2
A6: 1390 | B6: =IFERROR(VLOOKUP(Tabela1[[#This Row],[CC]],#REF!,5,0),"") | C6: JOSÉ NETO COELHO | D6: OI | E6: OI - DIGITAL SUPORT (1390) | F6: SERVIÇO | G6: 652 | H6: 44927 | I6: 33803.85 | J6: 32301.82 | K6: 44973 | L6: 45705 | M6: 45709 | N6: PAGO | O6: 0 | Q6: CSA | R6: UT | S6: =IFERROR(VLOOKUP(Tabela1[[#This Row],[CC]],CC!$A$1:$H$403,8,0),"") -> OP2 | T6: SIM | U6: RECUPERAÇÃO JUDICIAL
A7: 1390 | B7: =IFERROR(VLOOKUP(Tabela1[[#This Row],[CC]],#REF!,5,0),"") | C7: JOSÉ NETO COELHO | D7: OI | E7: OI - DIGITAL SUPORT (1390) | F7: SERVIÇO | G7: 652 | H7: 44927 | I7: 33803.85 | J7: 32301.82 | K7: 44973 | L7: 45733 | M7: 45736 | N7: PAGO | O7: 0 | Q7: CSA | R7: UT | S7: =IFERROR(VLOOKUP(Tabela1[[#This Row],[CC]],CC!$A$1:$H$403,8,0),"") -> OP2 | T7: SIM | U7: RECUPERAÇÃO JUDICIAL
A8: 1390 | B8: =IFERROR(VLOOKUP(Tabela1[[#This Row],[CC]],#REF!,5,0),"") | C8: JOSÉ NETO COELHO | D8: OI | E8: OI - DIGITAL SUPORT (1390) | F8: SERVIÇO | G8: 652 | H8: 44927 | I8: 33803.85 | J8: 32301.82 | K8: 44973 | L8: 45768 | M8: 45769 | N8: PAGO | O8: 0 | Q8: CSA | R8: UT | S8: =IFERROR(VLOOKUP(Tabela1[[#This Row],[CC]],CC!$A$1:$H$403,8,0),"") -> OP2 | T8: SIM | U8: RECUPERAÇÃO JUDICIAL
A9: 1390 | B9: =IFERROR(VLOOKUP(Tabela1[[#This Row],[CC]],#REF!,5,0),"") | C9: JOSÉ NETO COELHO | D9: OI | E9: OI - DIGITAL SUPORT (1390) | F9: SERVIÇO | G9: 652 | H9: 44927 | I9: 33803.85 | J9: 32301.82 | K9: 44973 | L9: 45796 | M9: 45798 | N9: PAGO | Q9: CSA | R9: UT | S9: =IFERROR(VLOOKUP(Tabela1[[#This Row],[CC]],CC!$A$1:$H$403,8,0),"") -> OP2 | T9: SIM | U9: RECUPERAÇÃO JUDICIAL
A10: 1398 | B10: =IFERROR(VLOOKUP(Tabela1[[#This Row],[CC]],#REF!,5,0),"") | C10: EVANDRO BRAGA | D10: COMPASS | E10: COMPASS (1398) | F10: SERVIÇO | G10: 8397 | H10: 45778 | I10: 275.56 | J10: 258.62 | K10: 45835 | L10: 45964 | M10: 45968 | N10: PAGO | O10: 0 | Q10: CSA | R10: UT | S10: =IFERROR(VLOOKUP(Tabela1[[#This Row],[CC]],CC!$A$1:$H$403,8,0),"") -> OP2
A11: 1398 | B11: =IFERROR(VLOOKUP(Tabela1[[#This Row],[CC]],#REF!,5,0),"") | C11: EVANDRO BRAGA | D11: COMPASS | E11: COMPASS (1398) | F11: SERVIÇO | G11: 8506 | H11: 45839 | I11: 75919.81 | J11: 71250.74 | K11: 45909 | L11: 45971 | M11: 45971 | N11: PAGO | O11: 0 | Q11: CSA | R11: UT | S11: =IFERROR(VLOOKUP(Tabela1[[#This Row],[CC]],CC!$A$1:$H$403,8,0),"") -> OP2
A12: 1398 | B12: =IFERROR(VLOOKUP(Tabela1[[#This Row],[CC]],#REF!,5,0),"") | C12: EVANDRO BRAGA | D12: COMPASS | E12: COMPASS (1398) | F12: SERVIÇO | G12: 8566 | H12: 45839 | I12: 22241.65 | J12: 20873.79 | K12: 45945 | L12: 45999 | M12: 46003 | N12: PAGO | O12: 0 | Q12: CSA | R12: UT | S12: =IFERROR(VLOOKUP(Tabela1[[#This Row],[CC]],CC!$A$1:$H$403,8,0),"") -> OP2
A13: 1398 | B13: =IFERROR(VLOOKUP(Tabela1[[#This Row],[CC]],#REF!,5,0),"") | C13: EVANDRO BRAGA | D13: COMPASS | E13: COMPASS (1398) | F13: SERVIÇO | G13: 8488 | H13: 45870 | I13: 48000 | J13: 45048 | K13: 45903 | L13: 45971 | M13: 45973 | N13: PAGO | O13: 0 | Q13: CSA | R13: UT | S13: =IFERROR(VLOOKUP(Tabela1[[#This Row],[CC]],CC!$A$1:$H$403,8,0),"") -> OP2
A14: 1398 | B14: =IFERROR(VLOOKUP(Tabela1[[#This Row],[CC]],#REF!,5,0),"") | C14: EVANDRO BRAGA | D14: COMPASS | E14: COMPASS (1398) | F14: SERVIÇO | G14: 8524 | H14: 45870 | I14: 75919.81 | J14: 71250.74 | K14: 45924 | L14: 45985 | M14: 45985 | N14: PAGO | O14: 0 | Q14: CSA | R14: UT | S14: =IFERROR(VLOOKUP(Tabela1[[#This Row],[CC]],CC!$A$1:$H$403,8,0),"") -> OP2
A15: 1398 | B15: =IFERROR(VLOOKUP(Tabela1[[#This Row],[CC]],#REF!,5,0),"") | C15: EVANDRO BRAGA | D15: COMPASS | E15: COMPASS (1398) | F15: SERVIÇO | G15: 8529 | H15: 45901 | I15: 48000 | J15: 45048 | K15: 45931 | L15: 45985 | M15: 45989 | N15: PAGO | O15: 0 | Q15: CSA | R15: UT | S15: =IFERROR(VLOOKUP(Tabela1[[#This Row],[CC]],CC!$A$1:$H$403,8,0),"") -> OP2
A16: 1390 | B16: =IFERROR(VLOOKUP(Tabela1[[#This Row],[CC]],#REF!,5,0),"") | C16: JOSÉ NETO COELHO | D16: OI | E16: OI - DIGITAL SUPORT (1390) | F16: SERVIÇO | G16: 1235 | H16: 45658 | I16: 191510.84 | J16: 169199.83 | K16: 45742 | L16: 45817 | M16: 45821 | N16: PAGO | O16: 0 | Q16: CSA | R16: UT | S16: =IFERROR(VLOOKUP(Tabela1[[#This Row],[CC]],CC!$A$1:$H$403,8,0),"") -> OP2
A17: 1455 | B17: =IFERROR(VLOOKUP(Tabela1[[#This Row],[CC]],#REF!,5,0),"") | C17: ROGERIO GORDILHO | D17: ATAKAREJO | E17: ATAKAREJO N3 (1455) | F17: SERVIÇO | G17: 1193 | H17: 45566 | I17: 3744 | J17: 3307.82 | K17: 45635 | L17: 45663 | M17: 45667 | N17: PAGO | O17: 0 | Q17: CSA | R17: MS | S17: =IFERROR(VLOOKUP(Tabela1[[#This Row],[CC]],CC!$A$1:$H$403,8,0),"") -> OP4
A18: 1398 | B18: =IFERROR(VLOOKUP(Tabela1[[#This Row],[CC]],#REF!,5,0),"") | C18: EVANDRO BRAGA | D18: COMPASS | E18: COMPASS (1398) | F18: SERVIÇO | G18: 8081 | H18: 45566 | I18: 36914.53 | J18: 34726.4 | K18: 45602 | L18: 45663 | M18: 45663 | N18: PAGO | O18: 0 | Q18: CSA | R18: UT | S18: =IFERROR(VLOOKUP(Tabela1[[#This Row],[CC]],CC!$A$1:$H$403,8,0),"") -> OP2
A19: 1398 | B19: =IFERROR(VLOOKUP(Tabela1[[#This Row],[CC]],#REF!,5,0),"") | C19: EVANDRO BRAGA | D19: COMPASS | E19: COMPASS (1398) | F19: SERVIÇO | G19: 8082 | H19: 45566 | I19: 11210.79 | J19: 10521.33 | K19: 45602 | L19: 45663 | M19: 45663 | N19: PAGO | O19: 0 | Q19: CSA | R19: UT | S19: =IFERROR(VLOOKUP(Tabela1[[#This Row],[CC]],CC!$A$1:$H$403,8,0),"") -> OP2
A20: 1398 | B20: =IFERROR(VLOOKUP(Tabela1[[#This Row],[CC]],#REF!,5,0),"") | C20: EVANDRO BRAGA | D20: COMPASS | E20: COMPASS (1398) | F20: SERVIÇO | G20: 8117 | H20: 45566 | I20: 13110.33 | J20: 12304.05 | K20: 45631 | L20: 45684 | M20: 45687 | N20: PAGO | O20: 0 | Q20: CSA | R20: UT | S20: =IFERROR(VLOOKUP(Tabela1[[#This Row],[CC]],CC!$A$1:$H$403,8,0),"") -> OP2
A21: 1398 | B21: =IFERROR(VLOOKUP(Tabela1[[#This Row],[CC]],#REF!,5,0),"") | C21: EVANDRO BRAGA | D21: COMPASS | E21: COMPASS (1398) | F21: SERVIÇO | G21: 8537 | H21: 45901 | I21: 26093.54 | J21: 24488.79 | K21: 45932 | L21: 45964 | M21: 45964 | N21: PAGO | O21: 0 | Q21: CSA | R21: UT | S21: =IFERROR(VLOOKUP(Tabela1[[#This Row],[CC]],CC!$A$1:$H$403,8,0),"") -> OP2
... A30: 1300 | B30: =IFERROR(VLOOKUP(Tabela1[[#This Row],[CC]],#REF!,5,0),"") | C30: JOSÉ NETO COELHO | D30: AXIA | E30: ELETROBRAS RS NOVO (1300) | F30: SERVIÇO | G30: 1200 | H30: 45597 | I30: 305213.15 | J30: 275760.08 | K30: 45642 | L30: 45670 | M30: 45672 | N30: PAGO | O30: 0 | Q30: CSA | R30: UT | S30: =IFERROR(VLOOKUP(Tabela1[[#This Row],[CC]],CC!$A$1:$H$403,8,0),"") -> OP2
A31: 1378 | B31: =IFERROR(VLOOKUP(Tabela1[[#This Row],[CC]],#REF!,5,0),"") | C31: RODRIGO CORUMBA | D31: FUNCEF | E31: SF – FUNCEF (1378) | F31: SERVIÇO | G31: 8160 | H31: 45597 | I31: 4281.29 | J31: 4017.99 | K31: 45643 | L31: 45663 | M31: 45666 | N31: PAGO | O31: 0 | Q31: BPS | R31: FS | S31: =IFERROR(VLOOKUP(Tabela1[[#This Row],[CC]],CC!$A$1:$H$403,8,0),"") -> OP2 | T31: SIM | U31: FATURADO - A RECEBER
A32: 1390 | B32: =IFERROR(VLOOKUP(Tabela1[[#This Row],[CC]],#REF!,5,0),"") | C32: JOSÉ NETO COELHO | D32: OI | E32: OI - DIGITAL SUPORT (1390) | F32: SERVIÇO | G32: 1252 | H32: 45689 | I32: 8840 | J32: 7810.14 | K32: 45791 | L32: 45852 | M32: 45855 | N32: PAGO | O32: 0 | Q32: CSA | R32: UT | S32: =IFERROR(VLOOKUP(Tabela1[[#This Row],[CC]],CC!$A$1:$H$403,8,0),"") -> OP2
A33: 1481 | B33: =IFERROR(VLOOKUP(Tabela1[[#This Row],[CC]],#REF!,5,0),"") | C33: RODRIGO CORUMBA | D33: SANTANDER | E33: SANTANDER ESFERA (1481) | F33: SERVIÇO | G33: 3728 | H33: 45597 | I33: 75283.92 | J33: 70653.96 | K33: 45642 | L33: 45663 | M33: 45667 | N33: PAGO | O33: 0 | Q33: ADS | R33: FS | S33: =IFERROR(VLOOKUP(Tabela1[[#This Row],[CC]],CC!$A$1:$H$403,8,0),"") -> OP2
A34: 1394 | B34: =IFERROR(VLOOKUP(Tabela1[[#This Row],[CC]],#REF!,5,0),"") | C34: ANTONIO ALVES | D34: SEFAZ_BA | E34: SEFAZ - BA DIGITAL CENTER (1394) | F34: SERVIÇO | G34: 8394 | H34: 45597 | I34: 52020 | J34: 48482.64 | K34: 45834 | L34: 45859 | M34: 45863 | N34: PAGO | Q34: CSA | R34: PS | S34: =IFERROR(VLOOKUP(Tabela1[[#This Row],[CC]],CC!$A$1:$H$403,8,0),"") -> OP4 | T34: Não existe
A35: 1394 | B35: =IFERROR(VLOOKUP(Tabela1[[#This Row],[CC]],#REF!,5,0),"") | C35: ANTONIO ALVES | D35: SEFAZ_BA | E35: SEFAZ - BA DIGITAL CENTER (1394) | F35: SERVIÇO | G35: 8395 | H35: 45597 | I35: 173413.32 | J35: 161621.21 | K35: 45834 | L35: 45873 | M35: 45875 | N35: PAGO | Q35: CSA | R35: PS | S35: =IFERROR(VLOOKUP(Tabela1[[#This Row],[CC]],CC!$A$1:$H$403,8,0),"") -> OP4 | T35: Não existe
A36: 1394 | B36: =IFERROR(VLOOKUP(Tabela1[[#This Row],[CC]],#REF!,5,0),"") | C36: ANTONIO ALVES | D36: SEFAZ_BA | E36: SEFAZ - BA DIGITAL CENTER (1394) | F36: SERVIÇO | G36: 8402 | H36: 45597 | I36: 77551.97 | J36: 72278.44 | K36: 45839 | L36: 45859 | M36: 45861 | N36: PAGO | Q36: CSA | R36: PS | S36: =IFERROR(VLOOKUP(Tabela1[[#This Row],[CC]],CC!$A$1:$H$403,8,0),"") -> OP4 | T36: Não existe
A37: 1394 | B37: =IFERROR(VLOOKUP(Tabela1[[#This Row],[CC]],#REF!,5,0),"") | C37: ANTONIO ALVES | D37: SEFAZ_BA | E37: SEFAZ - BA DIGITAL CENTER (1394) | F37: SERVIÇO | G37: 8404 | H37: 45597 | I37: 123.48 | J37: 115.08 | K37: 45839 | L37: 45866 | M37: 45867 | N37: PAGO | Q37: CSA | R37: PS | S37: =IFERROR(VLOOKUP(Tabela1[[#This Row],[CC]],CC!$A$1:$H$403,8,0),"") -> OP4 | T37: Não existe
A38: 1394 | B38: =IFERROR(VLOOKUP(Tabela1[[#This Row],[CC]],#REF!,5,0),"") | C38: ANTONIO ALVES | D38: SEFAZ_BA | E38: SEFAZ - BA DIGITAL CENTER (1394) | F38: SERVIÇO | G38: 8420 | H38: 45597 | I38: 47838.29 | J38: 44585.28 | K38: 45848 | L38: 45866 | M38: 45868 | N38: PAGO | Q38: CSA | R38: PS | S38: =IFERROR(VLOOKUP(Tabela1[[#This Row],[CC]],CC!$A$1:$H$403,8,0),"") -> OP4 | T38: Não existe
A39: 1394 | B39: =IFERROR(VLOOKUP(Tabela1[[#This Row],[CC]],#REF!,5,0),"") | C39: ANTONIO ALVES | D39: SEFAZ_BA | E39: SEFAZ - BA DIGITAL CENTER (1394) | F39: SERVIÇO | G39: 8421 | H39: 45597 | I39: 68299.32 | J39: 63654.96 | K39: 45849 | L39: 45870 | M39: 45870 | N39: PAGO | Q39: CSA | R39: PS | S39: =IFERROR(VLOOKUP(Tabela1[[#This Row],[CC]],CC!$A$1:$H$403,8,0),"") -> OP4 | T39: Não existe
A40: 1394 | B40: =IFERROR(VLOOKUP(Tabela1[[#This Row],[CC]],#REF!,5,0),"") | C40: ANTONIO ALVES | D40: SEFAZ_BA | E40: SEFAZ - BA DIGITAL CENTER (1394) | F40: SERVIÇO | G40: 8434 | H40: 45597 | I40: 96756.27 | J40: 90176.84 | K40: 45855 | L40: 45866 | M40: 45869 | N40: PAGO | Q40: CSA | R40: PS | S40: =IFERROR(VLOOKUP(Tabela1[[#This Row],[CC]],CC!$A$1:$H$403,8,0),"") -> OP4 | T40: Não existe
A41: 1394 | B41: =IFERROR(VLOOKUP(Tabela1[[#This Row],[CC]],#REF!,5,0),"") | C41: ANTONIO ALVES | D41: SEFAZ_BA | E41: SEFAZ - BA DIGITAL CENTER (1394) | F41: SERVIÇO | G41: 8438 | H41: 45597 | I41: 135430.28 | J41: 126221.02 | K41: 45859 | L41: 45887 | M41: 45887 | N41: PAGO | Q41: CSA | R41: PS | S41: =IFERROR(VLOOKUP(Tabela1[[#This Row],[CC]],CC!$A$1:$H$403,8,0),"") -> OP4 | T41: Não existe
A42: 1394 | B42: =IFERROR(VLOOKUP(Tabela1[[#This Row],[CC]],#REF!,5,0),"") | C42: ANTONIO ALVES | D42: SEFAZ_BA | E42: SEFAZ - BA DIGITAL CENTER (1394) | F42: SERVIÇO | G42: 8436 | H42: 45597 | I42: 10692.26 | J42: 9965.18 | K42: 45856 | L42: 45873 | M42: 45875 | N42: PAGO | O42: 0 | Q42: CSA | R42: PS | S42: =IFERROR(VLOOKUP(Tabela1[[#This Row],[CC]],CC!$A$1:$H$403,8,0),"") -> OP4
A43: 1360 | B43: =IFERROR(VLOOKUP(Tabela1[[#This Row],[CC]],#REF!,5,0),"") | C43: RITA ANDRADE | D43: SERASA | E43: SERASA EXPERIAN (1360) | F43: SERVIÇO | G43: 3731 | H43: 45597 | I43: 24312.4 | J43: 22817.19 | K43: 45644 | L43: 45698 | M43: 45700 | N43: PAGO | Q43: ADS | R43: FS | S43: =IFERROR(VLOOKUP(Tabela1[[#This Row],[CC]],CC!$A$1:$H$403,8,0),"") -> OP1
A44: 1483 | B44: =IFERROR(VLOOKUP(Tabela1[[#This Row],[CC]],#REF!,5,0),"") | C44: EVANDRO BRAGA | D44: UNIPAR | E44: UNIPAR (1483) | F44: SERVIÇO | G44: 8164 | H44: 45597 | I44: 28856.8 | J44: 26062.11 | K44: 45645 | L44: 45719 | M44: 45722 | N44: PAGO | O44: 0 | Q44: CSA | R44: UT | S44: =IFERROR(VLOOKUP(Tabela1[[#This Row],[CC]],CC!$A$1:$H$403,8,0),"") -> OP2
A45: 1483 | B45: =IFERROR(VLOOKUP(Tabela1[[#This Row],[CC]],#REF!,5,0),"") | C45: EVANDRO BRAGA | D45: UNIPAR | E45: UNIPAR (1483) | F45: SERVIÇO | G45: 8165 | H45: 45597 | I45: 53591.2 | J45: 48300.35 | K45: 45646 | L45: 45719 | M45: 45722 | N45: PAGO | O45: 0 | Q45: CSA | R45: UT | S45: =IFERROR(VLOOKUP(Tabela1[[#This Row],[CC]],CC!$A$1:$H$403,8,0),"") -> OP2
A46: 1455 | B46: =IFERROR(VLOOKUP(Tabela1[[#This Row],[CC]],#REF!,5,0),"") | C46: ROGERIO GORDILHO | D46: ATAKAREJO | E46: ATAKAREJO N3 (1455) | F46: SERVIÇO | G46: 1203 | H46: 45627 | I46: 54003.39 | J46: 47712 | K46: 45659 | L46: 45684 | M46: 45688 | N46: PAGO | Q46: CSA | R46: MS | S46: =IFERROR(VLOOKUP(Tabela1[[#This Row],[CC]],CC!$A$1:$H$403,8,0),"") -> OP4
A47: 1455 | B47: =IFERROR(VLOOKUP(Tabela1[[#This Row],[CC]],#REF!,5,0),"") | C47: ROGERIO GORDILHO | D47: ATAKAREJO | E47: ATAKAREJO N3 (1455) | F47: SERVIÇO | G47: 1205 | H47: 45627 | I47: 2857.25 | J47: 2524.38 | K47: 45663 | L47: 45684 | M47: 45688 | N47: PAGO | Q47: CSA | R47: MS | S47: =IFERROR(VLOOKUP(Tabela1[[#This Row],[CC]],CC!$A$1:$H$403,8,0),"") -> OP4
A48: 1455 | B48: =IFERROR(VLOOKUP(Tabela1[[#This Row],[CC]],#REF!,5,0),"") | C48: ROGERIO GORDILHO | D48: ATAKAREJO | E48: ATAKAREJO N3 (1455) | F48: SERVIÇO | G48: 1204 | H48: 45627 | I48: 2418 | J48: 2136.3 | K48: 45663 | L48: 45684 | M48: 45688 | N48: PAGO | Q48: CSA | R48: MS | S48: =IFERROR(VLOOKUP(Tabela1[[#This Row],[CC]],CC!$A$1:$H$403,8,0),"") -> OP4
...

Sheet Planilha1
B1: IR | C1: CSL
B2: 0.015 | C2: 0.0465
A3: 36666 | B3: =A3*$B$2 -> 549.99 | C3: =A3*$C$2 -> 1704.969
A4: 49671.04 | B4: =A4*$B$2 -> 745.0656 | C4: =A4*$C$2 -> 2309.7034
A5: 41449.6 | B5: =A5*$B$2 -> 621.744 | C5: =A5*$C$2 -> 1927.4064
