Workbook
Name DNOPE: 'PLANO DE CONTA'!$P$4:$P$14
Name DOPE: 'PLANO DE CONTA'!$N$4:$N$14
Name DRH: 'PLANO DE CONTA'!$R$4:$R$14
Name IMP: 'PLANO DE CONTA'!$T$4:$T$14
Name RNOP: 'PLANO DE CONTA'!$L$4:$L$11
Name RPROD: 'PLANO DE CONTA'!$H$4:$H$42
Name RSERV: 'PLANO DE CONTA'!$J$4:$J$42

Sheet PLANO DE CONTA
F2: BANCO | H2: RECEITA COM PRODUTO | J2: RECEITA COM SERVIÇO | L2: RECEITA NÃO OPERACIONAL | N2: DESPESAS OPERACIONAL | P2: DESPESAS NÃO OPERACIONAL | R2: DESPESAS COM RH | T2: IMPOSTOS
B3: COD | C3: CLASSIFICAÇÃO | D3: TIPO | H3: RPROD | J3: RSERV | L3: RNOPE | N3: DOPE | P3: DNOPE | R3: DRH | T3: IMP
H4: ANP | J4: ANP | L4: JUROS | N4: FACILITIES - FIXO | P4: MKT | R4: RH - VA/ VR - ALELO | T4: ICMS
B5: RPROD | C5: RECEITA COM PRODUTO | D5: RECEITA | F5: BRADESCO | H5: Arenas | J5: Arenas | L5: VENDA PRODUTOS | N5: REVENDA | P5: GESTÃO DE PESSOAS | R5: RH - PLANO DE SAÚDE | T5: IRRF
B6: RSERV | C6: RECEITA COM SERVIÇO | D6: RECEITA | F6: BB | H6: B. GAS | J6: B. GAS | N6: SERVIÇOS CONTÁBEIS | P6: TARIFA BANCÁRIA | R6: RH - TRANSPORTE | T6: ISS
B7: RNOPE | C7: RECEITA NÃO OPERACIONAL | D7: RECEITA | F7: BB -SP | H7: Bradesco | J7: Bradesco | N7: APORTE DE CAIXA | R7: RH - SALÁRIO | T7: IPTU
B8: DOPE | C8: DESPESAS OPERACIONAL | D8: DESPESAS | F8: SANTANDER | H8: BV Rendimento | J8: BV Rendimento | N8: LICENÇA DE SOFTWARE | R8: PAGAMENTO PJ | T8: FGTS
B9: DNOPE | C9: DESPESAS NÃO OPERACIONAIS | D9: DESPESAS | F9: ITAU | H9: CEABS | J9: CEABS | N9: FACILITIES - VARIÁVEL | R9: RH - FÉRIAS | T9: PIS
B10: DRH | C10: DESPESAS COM RH | D10: DESPESAS | H10: DG Cogel | J10: DG Cogel | R10: RH - DESLIGAMENTO | T10: COFINS
B11: IMP | C11: IMPOSTOS | D11: DESPESAS | H11: Ebal | J11: Ebal | R11: RH- BENEFÍCIOS
H12: Eletronuclear | J12: Eletronuclear
H13: EMBASA | J13: EMBASA
C14: DESPESAS COM RH | H14: Europ | J14: Europ
C15: DESPESAS NÃO OPERACIONAIS | H15: Fapesb | J15: Fapesb
H16: Furnas | J16: Furnas
H17: IBAMETRO | J17: IBAMETRO
H18: IBAMETRO | J18: IBAMETRO
H19: INEMA | J19: INEMA
H20: INEMA | J20: INEMA
H21: IPLAN | J21: IPLAN
H22: Irdeb | J22: Irdeb
H23: LE BISCUIT | J23: LE BISCUIT
H24: MP-BA | J24: MP-BA
H25: Nextia | J25: Nextia
H26: OI | J26: OI
H27: PETZ | J27: PETZ
... H42: UFBA | J42: UFBA

Sheet RELATÓRIO
A2: =TODAY() -> 46219
A4: BANCO | B4: SALDO
A5: Bradesco | B5: ='Fluxo do Banco'!G1467 -> 766908.08
A6: Santander | B6: ='Fluxo do Banco'!AK1467+'Fluxo do Banco'!AE1467 -> 18678.12
A7: Safra | B7: ='Fluxo do Banco'!AQ1467 -> 282.67
A8: Brasil | B8: ='Fluxo do Banco'!S1467 -> 267.78
A9: Brasil SP | B9: ='Fluxo do Banco'!Y1467 -> 58.41
A10: Itaú | B10: ='Fluxo do Banco'!M1467 -> -2921513.5
A11: ="Saldo Bancário em " & TEXT(TODAY(),"dd/mm/aaaa") -> Saldo Bancário em 16/07/2026 | B11: =SUM(B5:B10) -> -2135318.5
A12: Saldo Crédito INSS | B12: 5024000 | W12: 631770
A13: ="Saldo Operacional em " & TEXT(TODAY(),"dd/mm/aaaa") -> Saldo Operacional em 16/07/2026 | B13: =B11-B12 -> -7159318.5
A15: ="Recebimento " & TEXT(WORKDAY(TODAY(),-1),"dd/mm/aaaa") -> Recebimento 15/07/2026 | B15: =SUM(B16:B23) -> 1721472.9 | C15: ='Fluxo do Banco'!AT1467 -> 1721472.9 | D15: =C15-B15 -> 0 | W15: 89032
A16: SEC - BA | B16: 1555781.9
A17: FAPESB | B17: 80766.17
A18: INEMA | B18: 79968.13
A19: UNIPAR | B19: 4956.69
A24: ="Pagamento " & TEXT(WORKDAY(TODAY(),-1),"dd/mm/aaaa") -> Pagamento 15/07/2026 | B24: =SUM(B25:B37) -> 242432.41
A25: Despesas | B25: 242432.41
C27: ='Fluxo do Banco'!AV1467 -> -242432.41 | D27: =C27+B24 -> 0

Sheet Fluxo do Banco
BA1: =2.5%/30 -> 0.00083333333
C2: BRADESCO | I2: ITAÚ | O2: BB | U2: BB - SP | AA2: SANTANDER | AG2: SANTANDER SP | AM2: SAFRA | AS2: RESUMO | BD2: Soma de VALOR | BE2: Rótulos de Coluna
B3: DATA | C3: BRADESCO - SALDO INÍCIO | D3: BRADESCO - RECEBIMENTO | E3: BRADESCO - TRANSF ENTRE CONTAS | F3: BRADESCO - PAG | G3: BRADESCO - SALDO FINAL | H3: BRADESCO - LIMITES | I3: ITAÚ - SALDO | J3: ITAÚ - RECEBIMENTO | K3: ITAÚ -TRANSFENTRE CONTAS | L3: ITAÚ - PAG | M3: ITAÚ - SALDO FINAL | N3: ITAÚ- LIMITES | O3: BB - SALDO | P3: BB- RECEBIMENTO | Q3: BB - TRANSFENTRE CONTAS | R3: BB- PAG | S3: BB - SALDO FINAL | T3: BB- LIMITES | U3: BB -SP - SALDO | V3: BB-SP RECEBIMENTO | W3: BB - SP TRANSFENTRE CONTAS | X3: BB- SP - PAG | Y3: BB - SP - SALDO FINAL | Z3: BB- SP- LIMITES | AA3: SANTANDER - SALDO | AB3: SANTANDER - RECEBIMENTO | AC3: SANTANDER -TRANSFENTRE CONTAS | AD3: SANTANDER - PAGAMENTO | AE3: SANTANDER - SALDO FINAL | AF3: SANTANDER -LIMITES | AG3: SANTANDER - SALDO | AH3: SANTANDER - RECEBIMENTO | AI3: SANTANDER -TRANSFENTRE CONTAS | AJ3: SANTANDER - PAGAMENTO | AK3: SANTANDER - SALDO FINAL | AL3: SANTANDER -LIMITES | AM3: SAFRA - SALDO | AN3: SAFRA - RECEBIMENTO | AO3: SAFRA -TRANSFENTRE CONTAS | AP3: SAFRA - PAGAMENTO | AQ3: SAFRA - SALDO FINAL | AR3: SAFRA -LIMITES | AS3: BANCOS -SALDO | AT3: BANCOS -RECEBIMENTO | AU3: BANCOS -TRANSFENTRE CONTAS | AV3: BANCOS -PAGAMENTO | AW3: APLICAÇÃO | AX3: BANCOS - SALDO FINAL | AY3: BANCOS - LIMITES | AZ3: DISPONIVEL PARA PROX | BA3: Juros Diário | BB3: Acumulado Mês | BC3: Saldo médio | BD3: Rótulos de Linha | BE3: (vazio) | BF3: 30/nov | BG3: 01/dez | BH3: Total Geral
B4: 44165 | C4: 1655274.9 | D4: 369779.22 | F4: -157086.26 | G4: =SUM(C4:F4) -> 1867967.8 | H4: 3800000 | I4: 1335209.8 | J4: 663301.19 | L4: -11131.65 | M4: =SUM(I4:L4) -> 1987379.3 | N4: 2500000 | O4: 89001.46 | P4: 565656 | R4: -1654.8 | S4: =SUM(O4:R4) -> 653002.66 | U4: 915.97 | Y4: =SUM(U4:X4) -> 915.97 | AA4: 7904.2 | AD4: -1094.4 | AE4: =SUM(AA4:AD4) -> 6809.8 | AS4: =SUM(C4,I4,O4,U4,AA4,) -> 3088306.2 | AT4: =SUM(D4,J4,P4,V4,AB4,) -> 1598736.4 | AU4: =SUM(E4,K4,Q4,W4,AC4,) -> 0 | AV4: =SUM(F4,L4,R4,X4,AD4,) -> -170967.11 | AX4: =SUM(G4,M4,S4,Y4,AE4,) -> 4516075.5 | AY4: =SUM(H4,N4,T4,Z4,AF4,) -> 6300000 | AZ4: =AX4+AY4 -> 10816076 | BD4: BB | BF4: 653482.89 | BH4: 653482.89
B5: 44166 | C5: =G4 -> 1867967.8 | F5: -1126468 | G5: =SUM(C5:F5) -> 741499.82 | H5: 3800000 | I5: =M4 -> 1987379.3 | J5: 3.99 | L5: -1814471.9 | M5: =SUM(I5:L5) -> 172911.42 | N5: 2500000 | O5: =S4 -> 653002.66 | R5: -4579.51 | S5: =SUM(O5:R5) -> 648423.15 | U5: =Y4 -> 915.97 | V5: 401723.05 | Y5: =SUM(U5:X5) -> 402639.02 | AA5: =AE4 -> 6809.8 | AE5: =SUM(AA5:AD5) -> 6809.8 | AS5: =SUM(C5,I5,O5,U5,AA5,) -> 4516075.5 | AT5: =SUM(D5,J5,P5,V5,AB5,) -> 401727.04 | AU5: =SUM(E5,K5,Q5,W5,AC5,) -> 0 | AV5: =SUM(F5,L5,R5,X5,AD5,) -> -2945519.4 | AX5: =SUM(G5,M5,S5,Y5,AE5,) -> 1972283.2 | AY5: =SUM(H5,N5,T5,Z5,AF5,) -> 6300000 | AZ5: =AX5+AY5 -> 8272283.2 | BD5: DESPESAS | BF5: -1167.8 | BH5: -1167.8
B6: =B5+1 -> 44167 | C6: =G5 -> 741499.82 | D6: 387668.08 | E6: 450000 | F6: -126941.67 | G6: =SUM(C6:F6) -> 1452226.2 | H6: 3800000 | I6: =M5 -> 172911.42 | J6: 50542.57 | K6: 500000 | L6: -242377.01 | M6: =SUM(I6:L6) -> 481076.98 | N6: 2500000 | O6: =S5 -> 648423.15 | Q6: -600000 | R6: -21264.63 | S6: =SUM(O6:R6) -> 27158.52 | U6: =Y5 -> 402639.02 | W6: -400000 | X6: -54.95 | Y6: =SUM(U6:X6) -> 2584.07 | AA6: =AE5 -> 6809.8 | AC6: 50000 | AD6: -40790.98 | AE6: =SUM(AA6:AD6) -> 16018.82 | AS6: =SUM(C6,I6,O6,U6,AA6,) -> 1972283.2 | AT6: =SUM(D6,J6,P6,V6,AB6,) -> 438210.65 | AU6: =SUM(E6,K6,Q6,W6,AC6,) -> 0 | AV6: =SUM(F6,L6,R6,X6,AD6,) -> -431429.24 | AX6: =SUM(G6,M6,S6,Y6,AE6,) -> 1979064.6 | AY6: =SUM(H6,N6,T6,Z6,AF6,) -> 6300000 | AZ6: =AX6+AY6 -> 8279064.6 | BD6: RECEITA | BF6: 565649.23 | BH6: 565649.23
B7: =B6+1 -> 44168 | C7: =G6 -> 1452226.2 | D7: 275383.59 | F7: -88369.16 | G7: =SUM(C7:F7) -> 1639240.7 | H7: 3800000 | I7: =M6 -> 481076.98 | J7: 198.54 | L7: -104507.89 | M7: =SUM(I7:L7) -> 376767.63 | N7: 2500000 | O7: =S6 -> 27158.52 | S7: =SUM(O7:R7) -> 27158.52 | U7: =Y6 -> 2584.07 | X7: -1.2 | Y7: =SUM(U7:X7) -> 2582.87 | AA7: =AE6 -> 16018.82 | AB7: 35890.9 | AE7: =SUM(AA7:AD7) -> 51909.72 | AS7: =SUM(C7,I7,O7,U7,AA7,) -> 1979064.6 | AT7: =SUM(D7,J7,P7,V7,AB7,) -> 311473.03 | AU7: =SUM(E7,K7,Q7,W7,AC7,) -> 0 | AV7: =SUM(F7,L7,R7,X7,AD7,) -> -192878.25 | AX7: =SUM(G7,M7,S7,Y7,AE7,) -> 2097659.4 | AY7: =SUM(H7,N7,T7,Z7,AF7,) -> 6300000 | AZ7: =AX7+AY7 -> 8397659.4 | BD7: SALDO INICIAL | BF7: 89001.46 | BH7: 89001.46
B8: =B7+1 -> 44169 | C8: =G7 -> 1639240.7 | D8: 3.7 | F8: -10400 | G8: =SUM(C8:F8) -> 1628844.4 | H8: 3800000 | I8: =M7 -> 376767.63 | J8: 533835.99 | L8: -537 | M8: =SUM(I8:L8) -> 910066.62 | N8: 2500000 | O8: =S7 -> 27158.52 | P8: 174.42 | S8: =SUM(O8:R8) -> 27332.94 | U8: =Y7 -> 2582.87 | V8: 2760.29 | Y8: =SUM(U8:X8) -> 5343.16 | AA8: =AE7 -> 51909.72 | AE8: =SUM(AA8:AD8) -> 51909.72 | AS8: =SUM(C8,I8,O8,U8,AA8,) -> 2097659.4 | AT8: =SUM(D8,J8,P8,V8,AB8,) -> 536774.4 | AU8: =SUM(E8,K8,Q8,W8,AC8,) -> 0 | AV8: =SUM(F8,L8,R8,X8,AD8,) -> -10937 | AX8: =SUM(G8,M8,S8,Y8,AE8,) -> 2623496.8 | AY8: =SUM(H8,N8,T8,Z8,AF8,) -> 6300000 | AZ8: =AX8+AY8 -> 8923496.8 | BD8: BB -SP | BF8: 915.97 | BH8: 915.97
B9: =B8+3 -> 44172 | C9: =G8 -> 1628844.4 | F9: -747261.36 | G9: =SUM(C9:F9) -> 881583 | H9: 3800000 | I9: =M8 -> 910066.62 | J9: 193376.16 | L9: -35486.68 | M9: =SUM(I9:L9) -> 1067956.1 | N9: 2500000 | O9: =S8 -> 27332.94 | P9: 399.32 | Q9: 46000 | S9: =SUM(O9:R9) -> 73732.26 | U9: =Y8 -> 5343.16 | V9: 40993.68 | W9: -46000 | Y9: =SUM(U9:X9) -> 336.84 | AA9: =AE8 -> 51909.72 | AE9: =SUM(AA9:AD9) -> 51909.72 | AS9: =SUM(C9,I9,O9,U9,AA9,) -> 2623496.8 | AT9: =SUM(D9,J9,P9,V9,AB9,) -> 234769.16 | AU9: =SUM(E9,K9,Q9,W9,AC9,) -> 0 | AV9: =SUM(F9,L9,R9,X9,AD9,) -> -782748.04 | AX9: =SUM(G9,M9,S9,Y9,AE9,) -> 2075517.9 | AY9: =SUM(H9,N9,T9,Z9,AF9,) -> 6300000 | AZ9: =AX9+AY9 -> 8375517.9 | BD9: SALDO INICIAL | BF9: 915.97 | BH9: 915.97
B10: =B9+1 -> 44173 | C10: =G9 -> 881583 | D10: 131444 | F10: -93006.46 | G10: =SUM(C10:F10) -> 920020.54 | H10: 3800000 | I10: =M9 -> 1067956.1 | L10: -20112.33 | M10: =SUM(I10:L10) -> 1047843.8 | N10: 2500000 | O10: =S9 -> 73732.26 | S10: =SUM(O10:R10) -> 73732.26 | U10: =Y9 -> 336.84 | X10: -1.2 | Y10: =SUM(U10:X10) -> 335.64 | AA10: =AE9 -> 51909.72 | AE10: =SUM(AA10:AD10) -> 51909.72 | AS10: =SUM(C10,I10,O10,U10,AA10,) -> 2075517.9 | AT10: =SUM(D10,J10,P10,V10,AB10,) -> 131444 | AU10: =SUM(E10,K10,Q10,W10,AC10,) -> 0 | AV10: =SUM(F10,L10,R10,X10,AD10,) -> -113119.99 | AX10: =SUM(G10,M10,S10,Y10,AE10,) -> 2093841.9 | AY10: =SUM(H10,N10,T10,Z10,AF10,) -> 6300000 | AZ10: =AX10+AY10 -> 8393841.9 | BD10: BRADESCO | BF10: 1892167.6 | BH10: 1892167.6
B11: =B10+1 -> 44174 | C11: =G10 -> 920020.54 | D11: 45287.3 | F11: -26944.48 | G11: =SUM(C11:F11) -> 938363.36 | H11: 3800000 | I11: =M10 -> 1047843.8 | L11: -58597.6 | M11: =SUM(I11:L11) -> 989246.17 | N11: 2500000 | O11: =S10 -> 73732.26 | R11: -2062.9 | S11: =SUM(O11:R11) -> 71669.36 | U11: =Y10 -> 335.64 | Y11: =SUM(U11:X11) -> 335.64 | AA11: =AE10 -> 51909.72 | AE11: =SUM(AA11:AD11) -> 51909.72 | AS11: =SUM(C11,I11,O11,U11,AA11,) -> 2093841.9 | AT11: =SUM(D11,J11,P11,V11,AB11,) -> 45287.3 | AU11: =SUM(E11,K11,Q11,W11,AC11,) -> 0 | AV11: =SUM(F11,L11,R11,X11,AD11,) -> -87604.98 | AX11: =SUM(G11,M11,S11,Y11,AE11,) -> 2051524.3 | AY11: =SUM(H11,N11,T11,Z11,AF11,) -> 6300000 | AZ11: =AX11+AY11 -> 8351524.2 | BD11: DESPESAS | BF11: -132886.48 | BH11: -132886.48
B12: =B11+1 -> 44175 | C12: =G11 -> 938363.36 | D12: 478312.63 | F12: -178349.06 | G12: =SUM(C12:F12) -> 1238326.9 | H12: 3800000 | I12: =M11 -> 989246.17 | L12: -182658.69 | M12: =SUM(I12:L12) -> 806587.48 | N12: 2500000 | O12: =S11 -> 71669.36 | P12: 30325.1 | R12: -4001.94 | S12: =SUM(O12:R12) -> 97992.52 | U12: =Y11 -> 335.64 | Y12: =SUM(U12:X12) -> 335.64 | AA12: =AE11 -> 51909.72 | AD12: -221.25 | AE12: =SUM(AA12:AD12) -> 51688.47 | AS12: =SUM(C12,I12,O12,U12,AA12,) -> 2051524.3 | AT12: =SUM(D12,J12,P12,V12,AB12,) -> 508637.73 | AU12: =SUM(E12,K12,Q12,W12,AC12,) -> 0 | AV12: =SUM(F12,L12,R12,X12,AD12,) -> -365230.94 | AX12: =SUM(G12,M12,S12,Y12,AE12,) -> 2194931 | AY12: =SUM(H12,N12,T12,Z12,AF12,) -> 6300000 | AZ12: =AX12+AY12 -> 8494931 | BD12: RECEITA | BF12: 369779.22 | BH12: 369779.22
B13: =B12+1 -> 44176 | C13: =G12 -> 1238326.9 | F13: -10703.71 | G13: =SUM(C13:F13) -> 1227623.2 | H13: 3800000 | I13: =M12 -> 806587.48 | M13: =SUM(I13:L13) -> 806587.48 | N13: 2500000 | O13: =S12 -> 97992.52 | S13: =SUM(O13:R13) -> 97992.52 | U13: =Y12 -> 335.64 | Y13: =SUM(U13:X13) -> 335.64 | AA13: =AE12 -> 51688.47 | AE13: =SUM(AA13:AD13) -> 51688.47 | AS13: =SUM(C13,I13,O13,U13,AA13,) -> 2194931 | AT13: =SUM(D13,J13,P13,V13,AB13,) -> 0 | AU13: =SUM(E13,K13,Q13,W13,AC13,) -> 0 | AV13: =SUM(F13,L13,R13,X13,AD13,) -> -10703.71 | AX13: =SUM(G13,M13,S13,Y13,AE13,) -> 2184227.3 | AY13: =SUM(H13,N13,T13,Z13,AF13,) -> 6300000 | AZ13: =AX13+AY13 -> 8484227.3 | BD13: SALDO INICIAL | BF13: 1655274.9 | BH13: 1655274.9
B14: =B13+3 -> 44179 | C14: =G13 -> 1227623.2 | D14: 50628 | F14: -39041.48 | G14: =SUM(C14:F14) -> 1239209.7 | H14: 3800000 | I14: =M13 -> 806587.48 | J14: 1718696.3 | L14: -77055.6 | M14: =SUM(I14:L14) -> 2448228.2 | N14: 2500000 | O14: =S13 -> 97992.52 | R14: -4703.81 | S14: =SUM(O14:R14) -> 93288.71 | U14: =Y13 -> 335.64 | Y14: =SUM(U14:X14) -> 335.64 | AA14: =AE13 -> 51688.47 | AE14: =SUM(AA14:AD14) -> 51688.47 | AS14: =SUM(C14,I14,O14,U14,AA14,) -> 2184227.3 | AT14: =SUM(D14,J14,P14,V14,AB14,) -> 1769324.3 | AU14: =SUM(E14,K14,Q14,W14,AC14,) -> 0 | AV14: =SUM(F14,L14,R14,X14,AD14,) -> -120800.89 | AX14: =SUM(G14,M14,S14,Y14,AE14,) -> 3832750.8 | AY14: =SUM(H14,N14,T14,Z14,AF14,) -> 6300000 | AZ14: =AX14+AY14 -> 10132751 | BD14: ITAU | BF14: 1988314.3 | BH14: 1988314.3
B15: =B14+1 -> 44180 | C15: =G14 -> 1239209.7 | D15: 10251.03 | F15: -11250.05 | G15: =SUM(C15:F15) -> 1238210.7 | H15: 3800000 | I15: =M14 -> 2448228.2 | L15: -308622.69 | M15: =SUM(I15:L15) -> 2139605.5 | N15: 2500000 | O15: =S14 -> 93288.71 | R15: -704.6 | S15: =SUM(O15:R15) -> 92584.11 | U15: =Y14 -> 335.64 | Y15: =SUM(U15:X15) -> 335.64 | AA15: =AE14 -> 51688.47 | AE15: =SUM(AA15:AD15) -> 51688.47 | AS15: =SUM(C15,I15,O15,U15,AA15,) -> 3832750.8 | AT15: =SUM(D15,J15,P15,V15,AB15,) -> 10251.03 | AU15: =SUM(E15,K15,Q15,W15,AC15,) -> 0 | AV15: =SUM(F15,L15,R15,X15,AD15,) -> -320577.34 | AX15: =SUM(G15,M15,S15,Y15,AE15,) -> 3522424.5 | AY15: =SUM(H15,N15,T15,Z15,AF15,) -> 6300000 | AZ15: =AX15+AY15 -> 9822424.5 | BD15: DESPESAS | BF15: -10196.65 | BH15: -10196.65
B16: =B15+1 -> 44181 | C16: =G15 -> 1238210.7 | F16: -1187301.7 | G16: =SUM(C16:F16) -> 50909.01 | H16: 3800000 | I16: =M15 -> 2139605.5 | J16: 53228.4 | L16: -6202.99 | M16: =SUM(I16:L16) -> 2186630.9 | N16: 2500000 | O16: =S15 -> 92584.11 | S16: =SUM(O16:R16) -> 92584.11 | U16: =Y15 -> 335.64 | Y16: =SUM(U16:X16) -> 335.64 | AA16: =AE15 -> 51688.47 | AD16: -8755.4 | AE16: =SUM(AA16:AD16) -> 42933.07 | AS16: =SUM(C16,I16,O16,U16,AA16,) -> 3522424.5 | AT16: =SUM(D16,J16,P16,V16,AB16,) -> 53228.4 | AU16: =SUM(E16,K16,Q16,W16,AC16,) -> 0 | AV16: =SUM(F16,L16,R16,X16,AD16,) -> -1202260.1 | AX16: =SUM(G16,M16,S16,Y16,AE16,) -> 2373392.8 | AY16: =SUM(H16,N16,T16,Z16,AF16,) -> 6300000 | AZ16: =AX16+AY16 -> 8673392.8 | BD16: RECEITA | BF16: 663301.19 | BH16: 663301.19
B17: =B16+1 -> 44182 | C17: =G16 -> 50909.01 | D17: 4478.23 | F17: -76441.37 | G17: =SUM(C17:F17) -> -21054.13 | H17: 3800000 | I17: =M16 -> 2186630.9 | J17: 884193.57 | L17: -893162.29 | M17: =SUM(I17:L17) -> 2177662.2 | N17: 2500000 | O17: =S16 -> 92584.11 | R17: -80000 | S17: =SUM(O17:R17) -> 12584.11 | U17: =Y16 -> 335.64 | Y17: =SUM(U17:X17) -> 335.64 | AA17: =AE16 -> 42933.07 | AE17: =SUM(AA17:AD17) -> 42933.07 | AS17: =SUM(C17,I17,O17,U17,AA17,) -> 2373392.8 | AT17: =SUM(D17,J17,P17,V17,AB17,) -> 888671.8 | AU17: =SUM(E17,K17,Q17,W17,AC17,) -> 0 | AV17: =SUM(F17,L17,R17,X17,AD17,) -> -1049603.7 | AX17: =SUM(G17,M17,S17,Y17,AE17,) -> 2212460.9 | AY17: =SUM(H17,N17,T17,Z17,AF17,) -> 6300000 | AZ17: =AX17+AY17 -> 8512460.9 | BD17: SALDO INICIAL | BF17: 1335209.8 | BH17: 1335209.8
B18: =B17+1 -> 44183 | C18: =G17 -> -21054.13 | D18: 188826.81 | F18: -663193.6 | G18: =SUM(C18:F18) -> -495420.92 | H18: 3800000 | I18: =M17 -> 2177662.2 | J18: 814753.14 | L18: -78572.96 | M18: =SUM(I18:L18) -> 2913842.4 | N18: 2500000 | O18: =S17 -> 12584.11 | S18: =SUM(O18:R18) -> 12584.11 | U18: =Y17 -> 335.64 | Y18: =SUM(U18:X18) -> 335.64 | AA18: =AE17 -> 42933.07 | AE18: =SUM(AA18:AD18) -> 42933.07 | AS18: =SUM(C18,I18,O18,U18,AA18,) -> 2212460.9 | AT18: =SUM(D18,J18,P18,V18,AB18,) -> 1003579.9 | AU18: =SUM(E18,K18,Q18,W18,AC18,) -> 0 | AV18: =SUM(F18,L18,R18,X18,AD18,) -> -741766.56 | AX18: =SUM(G18,M18,S18,Y18,AE18,) -> 2474274.3 | AY18: =SUM(H18,N18,T18,Z18,AF18,) -> 6300000 | AZ18: =AX18+AY18 -> 8774274.3 | BD18: SANTANDER | BF18: 6809.8 | BH18: 6809.8
B19: =B18+3 -> 44186 | C19: =G18 -> -495420.92 | D19: 527175.93 | E19: 740000 | F19: -478547.62 | G19: =SUM(C19:F19) -> 293207.39 | H19: 3800000 | I19: =M18 -> 2913842.4 | J19: 553750.7 | K19: -1000000 | L19: -88946.66 | M19: =SUM(I19:L19) -> 2378646.4 | N19: 2500000 | O19: =S18 -> 12584.11 | P19: 95189.74 | R19: -4467.86 | S19: =SUM(O19:R19) -> 103305.99 | U19: =Y18 -> 335.64 | Y19: =SUM(U19:X19) -> 335.64 | AA19: =AE18 -> 42933.07 | AC19: 260000 | AE19: =SUM(AA19:AD19) -> 302933.07 | AS19: =SUM(C19,I19,O19,U19,AA19,) -> 2474274.3 | AT19: =SUM(D19,J19,P19,V19,AB19,) -> 1176116.4 | AU19: =SUM(E19,K19,Q19,W19,AC19,) -> 0 | AV19: =SUM(F19,L19,R19,X19,AD19,) -> -571962.14 | AX19: =SUM(G19,M19,S19,Y19,AE19,) -> 3078428.5 | AY19: =SUM(H19,N19,T19,Z19,AF19,) -> 6300000 | AZ19: =AX19+AY19 -> 9378428.5 | BD19: DESPESAS | BF19: -1094.4 | BH19: -1094.4
B20: =B19+1 -> 44187 | C20: =G19 -> 293207.39 | D20: 350141.95 | F20: -55721.49 | G20: =SUM(C20:F20) -> 587627.85 | H20: 3800000 | I20: =M19 -> 2378646.4 | J20: 33267.86 | L20: -18470.89 | M20: =SUM(I20:L20) -> 2393443.4 | N20: 2500000 | O20: =S19 -> 103305.99 | R20: -3590.98 | S20: =SUM(O20:R20) -> 99715.01 | U20: =Y19 -> 335.64 | Y20: =SUM(U20:X20) -> 335.64 | AA20: =AE19 -> 302933.07 | AB20: 43696.53 | AD20: -260364.98 | AE20: =SUM(AA20:AD20) -> 86264.62 | AS20: =SUM(C20,I20,O20,U20,AA20,) -> 3078428.5 | AT20: =SUM(D20,J20,P20,V20,AB20,) -> 427106.34 | AU20: =SUM(E20,K20,Q20,W20,AC20,) -> 0 | AV20: =SUM(F20,L20,R20,X20,AD20,) -> -338148.34 | AX20: =SUM(G20,M20,S20,Y20,AE20,) -> 3167386.5 | AY20: =SUM(H20,N20,T20,Z20,AF20,) -> 6300000 | AZ20: =AX20+AY20 -> 9467386.5 | BD20: SALDO INICIAL | BF20: 7904.2 | BH20: 7904.2
B21: =B20+1 -> 44188 | C21: =G20 -> 587627.85 | D21: 41783.76 | F21: -138.72 | G21: =SUM(C21:F21) -> 629272.89 | H21: 3800000 | I21: =M20 -> 2393443.4 | J21: 212577.98 | M21: =SUM(I21:L21) -> 2606021.4 | N21: 2500000 | O21: =S20 -> 99715.01 | P21: 81.92 | S21: =SUM(O21:R21) -> 99796.93 | U21: =Y20 -> 335.64 | Y21: =SUM(U21:X21) -> 335.64 | AA21: =AE20 -> 86264.62 | AE21: =SUM(AA21:AD21) -> 86264.62 | AS21: =SUM(C21,I21,O21,U21,AA21,) -> 3167386.5 | AT21: =SUM(D21,J21,P21,V21,AB21,) -> 254443.66 | AU21: =SUM(E21,K21,Q21,W21,AC21,) -> 0 | AV21: =SUM(F21,L21,R21,X21,AD21,) -> -138.72 | AX21: =SUM(G21,M21,S21,Y21,AE21,) -> 3421691.5 | AY21: =SUM(H21,N21,T21,Z21,AF21,) -> 6300000 | AZ21: =AX21+AY21 -> 9721691.5 | BD21: (vazio)
B22: =B21+1 -> 44189 | C22: =G21 -> 629272.89 | D22: 324875.07 | F22: -60000 | G22: =SUM(C22:F22) -> 894147.96 | H22: 3800000 | I22: =M21 -> 2606021.4 | M22: =SUM(I22:L22) -> 2606021.4 | N22: 2500000 | O22: =S21 -> 99796.93 | P22: 81.92 | S22: =SUM(O22:R22) -> 99878.85 | U22: =Y21 -> 335.64 | Y22: =SUM(U22:X22) -> 335.64 | AA22: =AE21 -> 86264.62 | AE22: =SUM(AA22:AD22) -> 86264.62 | AS22: =SUM(C22,I22,O22,U22,AA22,) -> 3421691.5 | AT22: =SUM(D22,J22,P22,V22,AB22,) -> 324956.99 | AU22: =SUM(E22,K22,Q22,W22,AC22,) -> 0 | AV22: =SUM(F22,L22,R22,X22,AD22,) -> -60000 | AX22: =SUM(G22,M22,S22,Y22,AE22,) -> 3686648.5 | AY22: =SUM(H22,N22,T22,Z22,AF22,) -> 6300000 | AZ22: =AX22+AY22 -> 9986648.5 | BD22: DESPESAS
B23: =B22+4 -> 44193 | C23: =G22 -> 894147.96 | D23: 462678.1 | F23: -246712.73 | G23: =SUM(C23:F23) -> 1110113.3 | H23: 3800000 | I23: =M22 -> 2606021.4 | L23: -243988.47 | M23: =SUM(I23:L23) -> 2362032.9 | N23: 2500000 | O23: =S22 -> 99878.85 | R23: -3428.09 | S23: =SUM(O23:R23) -> 96450.76 | U23: =Y22 -> 335.64 | Y23: =SUM(U23:X23) -> 335.64 | AA23: =AE22 -> 86264.62 | AD23: -9133.24 | AE23: =SUM(AA23:AD23) -> 77131.38 | AS23: =SUM(C23,I23,O23,U23,AA23,) -> 3686648.5 | AT23: =SUM(D23,J23,P23,V23,AB23,) -> 462678.1 | AU23: =SUM(E23,K23,Q23,W23,AC23,) -> 0 | AV23: =SUM(F23,L23,R23,X23,AD23,) -> -503262.53 | AX23: =SUM(G23,M23,S23,Y23,AE23,) -> 3646064 | AY23: =SUM(H23,N23,T23,Z23,AF23,) -> 6300000 | AZ23: =AX23+AY23 -> 9946064 | BD23: #N/D
B24: =B23+1 -> 44194 | C24: =G23 -> 1110113.3 | D24: 45385.53 | F24: -149121.85 | G24: =SUM(C24:F24) -> 1006377 | H24: 3800000 | I24: =M23 -> 2362032.9 | L24: -165 | M24: =SUM(I24:L24) -> 2361867.9 | N24: 2500000 | O24: =S23 -> 96450.76 | S24: =SUM(O24:R24) -> 96450.76 | U24: =Y23 -> 335.64 | Y24: =SUM(U24:X24) -> 335.64 | AA24: =AE23 -> 77131.38 | AE24: =SUM(AA24:AD24) -> 77131.38 | AS24: =SUM(C24,I24,O24,U24,AA24,) -> 3646064 | AT24: =SUM(D24,J24,P24,V24,AB24,) -> 45385.53 | AU24: =SUM(E24,K24,Q24,W24,AC24,) -> 0 | AV24: =SUM(F24,L24,R24,X24,AD24,) -> -149286.85 | AX24: =SUM(G24,M24,S24,Y24,AE24,) -> 3542162.7 | AY24: =SUM(H24,N24,T24,Z24,AF24,) -> 6300000 | AZ24: =AX24+AY24 -> 9842162.7 | BD24: Total Geral | BF24: 4541690.6 | BH24: 4541690.6
B25: =B24+1 -> 44195 | C25: =G24 -> 1006377 | D25: 37433.69 | F25: -35336.74 | G25: =SUM(C25:F25) -> 1008474 | H25: 3800000 | I25: =M24 -> 2361867.9 | J25: 330127.77 | L25: -360077.33 | M25: =SUM(I25:L25) -> 2331918.4 | N25: 2500000 | O25: =S24 -> 96450.76 | P25: 240834.73 | S25: =SUM(O25:R25) -> 337285.49 | U25: =Y24 -> 335.64 | Y25: =SUM(U25:X25) -> 335.64 | AA25: =AE24 -> 77131.38 | AE25: =SUM(AA25:AD25) -> 77131.38 | AS25: =SUM(C25,I25,O25,U25,AA25,) -> 3542162.7 | AT25: =SUM(D25,J25,P25,V25,AB25,) -> 608396.19 | AU25: =SUM(E25,K25,Q25,W25,AC25,) -> 0 | AV25: =SUM(F25,L25,R25,X25,AD25,) -> -395414.07 | AX25: =SUM(G25,M25,S25,Y25,AE25,) -> 3755144.8 | AY25: =SUM(H25,N25,T25,Z25,AF25,) -> 6300000 | AZ25: =AX25+AY25 -> 10055145
B26: =B25+1 -> 44196 | C26: =G25 -> 1008474 | G26: =SUM(C26:F26) -> 1008474 | H26: 3800000 | I26: =M25 -> 2331918.4 | J26: =106756.36+107508.93 -> 214265.29 | M26: =SUM(I26:L26) -> 2546183.6 | N26: 2500000 | O26: =S25 -> 337285.49 | S26: =SUM(O26:R26) -> 337285.49 | U26: =Y25 -> 335.64 | Y26: =SUM(U26:X26) -> 335.64 | AA26: =AE25 -> 77131.38 | AE26: =SUM(AA26:AD26) -> 77131.38 | AS26: =SUM(C26,I26,O26,U26,AA26,) -> 3755144.8 | AT26: =SUM(D26,J26,P26,V26,AB26,) -> 214265.29 | AU26: =SUM(E26,K26,Q26,W26,AC26,) -> 0 | AV26: =SUM(F26,L26,R26,X26,AD26,) -> 0 | AX26: =SUM(G26,M26,S26,Y26,AE26,) -> 3969410.1 | AY26: =SUM(H26,N26,T26,Z26,AF26,) -> 6300000 | AZ26: =AX26+AY26 -> 10269410
B27: =B26+4 -> 44200 | C27: =G26 -> 1008474 | D27: 217048.98 | F27: -237325.38 | G27: =SUM(C27:F27) -> 988197.56 | H27: 3800000 | I27: =M26 -> 2546183.6 | J27: 389097.9 | L27: -1779947.4 | M27: =SUM(I27:L27) -> 1155334.1 | N27: 2500000 | O27: =S26 -> 337285.49 | P27: 26162.55 | R27: -2600 | S27: =SUM(O27:R27) -> 360848.04 | U27: =Y26 -> 335.64 | V27: 458774.3 | Y27: =SUM(U27:X27) -> 459109.94 | AA27: =AE26 -> 77131.38 | AB27: 0.6 | AE27: =SUM(AA27:AD27) -> 77131.98 | AS27: =SUM(C27,I27,O27,U27,AA27,) -> 3969410.1 | AT27: =SUM(D27,J27,P27,V27,AB27,) -> 1091084.3 | AU27: =SUM(E27,K27,Q27,W27,AC27,) -> 0 | AV27: =SUM(F27,L27,R27,X27,AD27,) -> -2019872.8 | AX27: =SUM(G27,M27,S27,Y27,AE27,) -> 3040621.6 | AY27: =SUM(H27,N27,T27,Z27,AF27,) -> 6300000 | AZ27: =AX27+AY27 -> 9340621.6
B28: =B27+1 -> 44201 | C28: =G27 -> 988197.56 | D28: 1351.1 | F28: -759334.44 | G28: =SUM(C28:F28) -> 230214.22 | H28: 3800000 | I28: =M27 -> 1155334.1 | L28: -214032.36 | M28: =SUM(I28:L28) -> 941301.75 | N28: 2500000 | O28: =S27 -> 360848.04 | S28: =SUM(O28:R28) -> 360848.04 | U28: =Y27 -> 459109.94 | X28: -54.95 | Y28: =SUM(U28:X28) -> 459054.99 | AA28: =AE27 -> 77131.98 | AE28: =SUM(AA28:AD28) -> 77131.98 | AS28: =SUM(C28,I28,O28,U28,AA28,) -> 3040621.6 | AT28: =SUM(D28,J28,P28,V28,AB28,) -> 1351.1 | AU28: =SUM(E28,K28,Q28,W28,AC28,) -> 0 | AV28: =SUM(F28,L28,R28,X28,AD28,) -> -973421.75 | AX28: =SUM(G28,M28,S28,Y28,AE28,) -> 2068551 | AY28: =SUM(H28,N28,T28,Z28,AF28,) -> 6300000 | AZ28: =AX28+AY28 -> 8368551
B29: =B28+1 -> 44202 | C29: =G28 -> 230214.22 | D29: =119338.75+163732.17 -> 283070.92 | F29: -58313.83 | G29: =SUM(C29:F29) -> 454971.31 | H29: 3800000 | I29: =M28 -> 941301.75 | L29: -52555.57 | M29: =SUM(I29:L29) -> 888746.18 | N29: 2500000 | O29: =S28 -> 360848.04 | R29: -522.5 | S29: =SUM(O29:R29) -> 360325.54 | U29: =Y28 -> 459054.99 | Y29: =SUM(U29:X29) -> 459054.99 | AA29: =AE28 -> 77131.98 | AE29: =SUM(AA29:AD29) -> 77131.98 | AS29: =SUM(C29,I29,O29,U29,AA29,) -> 2068551 | AT29: =SUM(D29,J29,P29,V29,AB29,) -> 283070.92 | AU29: =SUM(E29,K29,Q29,W29,AC29,) -> 0 | AV29: =SUM(F29,L29,R29,X29,AD29,) -> -111391.9 | AX29: =SUM(G29,M29,S29,Y29,AE29,) -> 2240230 | AY29: =SUM(H29,N29,T29,Z29,AF29,) -> 6300000 | AZ29: =AX29+AY29 -> 8540230
B30: =B29+1 -> 44203 | C30: =G29 -> 454971.31 | D30: 322579.04 | G30: =SUM(C30:F30) -> 777550.35 | H30: 3800000 | I30: =M29 -> 888746.18 | L30: -412305.85 | M30: =SUM(I30:L30) -> 476440.33 | N30: 2500000 | O30: =S29 -> 360325.54 | S30: =SUM(O30:R30) -> 360325.54 | U30: =Y29 -> 459054.99 | Y30: =SUM(U30:X30) -> 459054.99 | AA30: =AE29 -> 77131.98 | AE30: =SUM(AA30:AD30) -> 77131.98 | AS30: =SUM(C30,I30,O30,U30,AA30,) -> 2240230 | AT30: =SUM(D30,J30,P30,V30,AB30,) -> 322579.04 | AU30: =SUM(E30,K30,Q30,W30,AC30,) -> 0 | AV30: =SUM(F30,L30,R30,X30,AD30,) -> -412305.85 | AX30: =SUM(G30,M30,S30,Y30,AE30,) -> 2150503.2 | AY30: =SUM(H30,N30,T30,Z30,AF30,) -> 6300000 | AZ30: =AX30+AY30 -> 8450503.2
B31: =B30+1 -> 44204 | C31: =G30 -> 777550.35 | D31: 50372.93 | F31: -5552.87 | G31: =SUM(C31:F31) -> 822370.41 | H31: 3800000 | I31: =M30 -> 476440.33 | J31: 136082.5 | M31: =SUM(I31:L31) -> 612522.83 | N31: 2500000 | O31: =S30 -> 360325.54 | S31: =SUM(O31:R31) -> 360325.54 | U31: =Y30 -> 459054.99 | Y31: =SUM(U31:X31) -> 459054.99 | AA31: =AE30 -> 77131.98 | AE31: =SUM(AA31:AD31) -> 77131.98 | AS31: =SUM(C31,I31,O31,U31,AA31,) -> 2150503.2 | AT31: =SUM(D31,J31,P31,V31,AB31,) -> 186455.43 | AU31: =SUM(E31,K31,Q31,W31,AC31,) -> 0 | AV31: =SUM(F31,L31,R31,X31,AD31,) -> -5552.87 | AX31: =SUM(G31,M31,S31,Y31,AE31,) -> 2331405.8 | AY31: =SUM(H31,N31,T31,Z31,AF31,) -> 6300000 | AZ31: =AX31+AY31 -> 8631405.8
B32: =B31+3 -> 44207 | C32: =G31 -> 822370.41 | D32: 461960.48 | F32: -299985.12 | G32: =SUM(C32:F32) -> 984345.77 | H32: 3800000 | I32: =M31 -> 612522.83 | L32: -82130.02 | M32: =SUM(I32:L32) -> 530392.81 | N32: 2500000 | O32: =S31 -> 360325.54 | R32: -1440 | S32: =SUM(O32:R32) -> 358885.54 | U32: =Y31 -> 459054.99 | V32: 57042.31 | Y32: =SUM(U32:X32) -> 516097.3 | AA32: =AE31 -> 77131.98 | AD32: -8531.53 | AE32: =SUM(AA32:AD32) -> 68600.45 | AS32: =SUM(C32,I32,O32,U32,AA32,) -> 2331405.8 | AT32: =SUM(D32,J32,P32,V32,AB32,) -> 519002.79 | AU32: =SUM(E32,K32,Q32,W32,AC32,) -> 0 | AV32: =SUM(F32,L32,R32,X32,AD32,) -> -392086.67 | AX32: =SUM(G32,M32,S32,Y32,AE32,) -> 2458321.9 | AY32: =SUM(H32,N32,T32,Z32,AF32,) -> 6300000 | AZ32: =AX32+AY32 -> 8758321.9
B33: =B32+1 -> 44208 | C33: =G32 -> 984345.77 | D33: 244010 | F33: -46159.84 | G33: =SUM(C33:F33) -> 1182195.9 | H33: 3800000 | I33: =M32 -> 530392.81 | J33: 94050.03 | L33: -60294.29 | M33: =SUM(I33:L33) -> 564148.55 | N33: 2500000 | O33: =S32 -> 358885.54 | Q33: 516000 | S33: =SUM(O33:R33) -> 874885.54 | U33: =Y32 -> 516097.3 | W33: -516000 | Y33: =SUM(U33:X33) -> 97.3 | AA33: =AE32 -> 68600.45 | AD33: -7566.43 | AE33: =SUM(AA33:AD33) -> 61034.02 | AS33: =SUM(C33,I33,O33,U33,AA33,) -> 2458321.9 | AT33: =SUM(D33,J33,P33,V33,AB33,) -> 338060.03 | AU33: =SUM(E33,K33,Q33,W33,AC33,) -> 0 | AV33: =SUM(F33,L33,R33,X33,AD33,) -> -114020.56 | AX33: =SUM(G33,M33,S33,Y33,AE33,) -> 2682361.3 | AY33: =SUM(H33,N33,T33,Z33,AF33,) -> 6300000 | AZ33: =AX33+AY33 -> 8982361.3
B34: =B33+1 -> 44209 | C34: =G33 -> 1182195.9 | D34: 142960.28 | E34: =800000-300000 -> 500000 | F34: -2692.59 | G34: =SUM(C34:F34) -> 1822463.6 | H34: 3800000 | I34: =M33 -> 564148.55 | L34: -4559.35 | M34: =SUM(I34:L34) -> 559589.2 | N34: 2500000 | O34: =S33 -> 874885.54 | Q34: -800000 | S34: =SUM(O34:R34) -> 74885.54 | U34: =Y33 -> 97.3 | Y34: =SUM(U34:X34) -> 97.3 | AA34: =AE33 -> 61034.02 | AC34: 300000 | AD34: -435 | AE34: =SUM(AA34:AD34) -> 360599.02 | AS34: =SUM(C34,I34,O34,U34,AA34,) -> 2682361.3 | AT34: =SUM(D34,J34,P34,V34,AB34,) -> 142960.28 | AU34: =SUM(E34,K34,Q34,W34,AC34,) -> 0 | AV34: =SUM(F34,L34,R34,X34,AD34,) -> -7686.94 | AX34: =SUM(G34,M34,S34,Y34,AE34,) -> 2817634.7 | AY34: =SUM(H34,N34,T34,Z34,AF34,) -> 6300000 | AZ34: =AX34+AY34 -> 9117634.7
B35: =B34+1 -> 44210 | C35: =G34 -> 1822463.6 | D35: 2406759.4 | F35: -5057.31 | G35: =SUM(C35:F35) -> 4224165.7 | H35: 3800000 | I35: =M34 -> 559589.2 | J35: 375.68 | L35: -58718.61 | M35: =SUM(I35:L35) -> 501246.27 | N35: 2500000 | O35: =S34 -> 74885.54 | P35: =188.16*2 -> 376.32 | S35: =SUM(O35:R35) -> 75261.86 | U35: =Y34 -> 97.3 | Y35: =SUM(U35:X35) -> 97.3 | AA35: =AE34 -> 360599.02 | AE35: =SUM(AA35:AD35) -> 360599.02 | AS35: =SUM(C35,I35,O35,U35,AA35,) -> 2817634.7 | AT35: =SUM(D35,J35,P35,V35,AB35,) -> 2407511.4 | AU35: =SUM(E35,K35,Q35,W35,AC35,) -> 0 | AV35: =SUM(F35,L35,R35,X35,AD35,) -> -63775.92 | AX35: =SUM(G35,M35,S35,Y35,AE35,) -> 5161370.1 | AY35: =SUM(H35,N35,T35,Z35,AF35,) -> 6300000 | AZ35: =AX35+AY35 -> 11461370
B36: =B35+1 -> 44211 | C36: =G35 -> 4224165.7 | D36: =2858.78 -> 2858.78 | F36: -3825.99 | G36: =SUM(C36:F36) -> 4223198.5 | H36: 3800000 | I36: =M35 -> 501246.27 | L36: -265899.16 | M36: =SUM(I36:L36) -> 235347.11 | N36: 2500000 | O36: =S35 -> 75261.86 | S36: =SUM(O36:R36) -> 75261.86 | U36: =Y35 -> 97.3 | Y36: =SUM(U36:X36) -> 97.3 | AA36: =AE35 -> 360599.02 | AE36: =SUM(AA36:AD36) -> 360599.02 | AS36: =SUM(C36,I36,O36,U36,AA36,) -> 5161370.1 | AT36: =SUM(D36,J36,P36,V36,AB36,) -> 2858.78 | AU36: =SUM(E36,K36,Q36,W36,AC36,) -> 0 | AV36: =SUM(F36,L36,R36,X36,AD36,) -> -269725.15 | AX36: =SUM(G36,M36,S36,Y36,AE36,) -> 4894503.8 | AY36: =SUM(H36,N36,T36,Z36,AF36,) -> 6300000 | AZ36: =AX36+AY36 -> 11194504
B37: =B36+3 -> 44214 | C37: =G36 -> 4223198.5 | D37: =44963.89+8658.6+11580.8 -> 65203.29 | F37: -13956.6 | G37: =SUM(C37:F37) -> 4274445.2 | H37: 3800000 | I37: =M36 -> 235347.11 | L37: -79739.64 | M37: =SUM(I37:L37) -> 155607.47 | N37: 2500000 | O37: =S36 -> 75261.86 | S37: =SUM(O37:R37) -> 75261.86 | U37: =Y36 -> 97.3 | Y37: =SUM(U37:X37) -> 97.3 | AA37: =AE36 -> 360599.02 | AD37: -158.36 | AE37: =SUM(AA37:AD37) -> 360440.66 | AS37: =SUM(C37,I37,O37,U37,AA37,) -> 4894503.8 | AT37: =SUM(D37,J37,P37,V37,AB37,) -> 65203.29 | AU37: =SUM(E37,K37,Q37,W37,AC37,) -> 0 | AV37: =SUM(F37,L37,R37,X37,AD37,) -> -93854.6 | AX37: =SUM(G37,M37,S37,Y37,AE37,) -> 4865852.4 | AY37: =SUM(H37,N37,T37,Z37,AF37,) -> 6300000 | AZ37: =AX37+AY37 -> 11165852
B38: =B37+1 -> 44215 | C38: =G37 -> 4274445.2 | D38: 35990.84 | F38: -490613.49 | G38: =SUM(C38:F38) -> 3819822.5 | H38: 3800000 | I38: =M37 -> 155607.47 | L38: -32668.15 | M38: =SUM(I38:L38) -> 122939.32 | N38: 2500000 | O38: =S37 -> 75261.86 | R38: =-632.4-348 -> -980.4 | S38: =SUM(O38:R38) -> 74281.46 | U38: =Y37 -> 97.3 | Y38: =SUM(U38:X38) -> 97.3 | AA38: =AE37 -> 360440.66 | AD38: -12797.53 | AE38: =SUM(AA38:AD38) -> 347643.13 | AS38: =SUM(C38,I38,O38,U38,AA38,) -> 4865852.4 | AT38: =SUM(D38,J38,P38,V38,AB38,) -> 35990.84 | AU38: =SUM(E38,K38,Q38,W38,AC38,) -> 0 | AV38: =SUM(F38,L38,R38,X38,AD38,) -> -537059.57 | AX38: =SUM(G38,M38,S38,Y38,AE38,) -> 4364783.7 | AY38: =SUM(H38,N38,T38,Z38,AF38,) -> 6300000 | AZ38: =AX38+AY38 -> 10664784
B39: =B38+1 -> 44216 | C39: =G38 -> 3819822.5 | F39: -994587.75 | G39: =SUM(C39:F39) -> 2825234.8 | H39: 3800000 | I39: =M38 -> 122939.32 | L39: -2694.53 | M39: =SUM(I39:L39) -> 120244.79 | N39: 2500000 | O39: =S38 -> 74281.46 | S39: =SUM(O39:R39) -> 74281.46 | U39: =Y38 -> 97.3 | Y39: =SUM(U39:X39) -> 97.3 | AA39: =AE38 -> 347643.13 | AD39: -20374.2 | AE39: =SUM(AA39:AD39) -> 327268.93 | AS39: =SUM(C39,I39,O39,U39,AA39,) -> 4364783.7 | AT39: =SUM(D39,J39,P39,V39,AB39,) -> 0 | AU39: =SUM(E39,K39,Q39,W39,AC39,) -> 0 | AV39: =SUM(F39,L39,R39,X39,AD39,) -> -1017656.5 | AX39: =SUM(G39,M39,S39,Y39,AE39,) -> 3347127.2 | AY39: =SUM(H39,N39,T39,Z39,AF39,) -> 6300000 | AZ39: =AX39+AY39 -> 9647127.2
B40: =B39+1 -> 44217 | C40: =G39 -> 2825234.8 | D40: =22692.82*2+84283.33 -> 129668.97 | F40: -204.25 | G40: =SUM(C40:F40) -> 2954699.5 | H40: 3800000 | I40: =M39 -> 120244.79 | L40: -23095.26 | M40: =SUM(I40:L40) -> 97149.53 | N40: 2500000 | O40: =S39 -> 74281.46 | S40: =SUM(O40:R40) -> 74281.46 | U40: =Y39 -> 97.3 | Y40: =SUM(U40:X40) -> 97.3 | AA40: =AE39 -> 327268.93 | AD40: -257401.79 | AE40: =SUM(AA40:AD40) -> 69867.14 | AS40: =SUM(C40,I40,O40,U40,AA40,) -> 3347127.2 | AT40: =SUM(D40,J40,P40,V40,AB40,) -> 129668.97 | AU40: =SUM(E40,K40,Q40,W40,AC40,) -> 0 | AV40: =SUM(F40,L40,R40,X40,AD40,) -> -280701.3 | AX40: =SUM(G40,M40,S40,Y40,AE40,) -> 3196094.9 | AY40: =SUM(H40,N40,T40,Z40,AF40,) -> 6300000 | AZ40: =AX40+AY40 -> 9496094.9
...
